<mujoco model="simplecar">
  <compiler angle="radian"/>
  <option gravity="0 0 -9.81"/>

  <asset>
    <texture type="skybox" builtin="gradient" rgb1="0.3 0.5 0.7" rgb2="0 0 0" width="512" height="512"/>
    <texture name="texplane" type="2d" builtin="checker" rgb1="0.2 0.3 0.4" rgb2="0.1 0.2 0.3" width="512" height="512" mark="cross" markrgb=".8 .8 .8"/>
    <material name="matplane" texture="texplane" texrepeat="1 1" texuniform="true" reflectance="0.2"/>
  </asset>

  <worldbody>
    <!-- floor -->
    <geom name="floor" pos="0 0 0" size="100 100 0.1" type="plane" material="matplane"/>

    <body name="left_hinge" pos="0.2 0 0">
      <inertial pos="0 0 0" mass="0.01" diaginertia="5e-06 5e-06 5e-06"/>
      <joint name="base_to_left_hinge" pos="0 0 0" axis="0 0 1" range="-0.5 0.5" actuatorfrcrange="-100 100"/>
      <body name="left_front_wheel" pos="0 0.2 0">
        <inertial pos="0 0 0" mass="0.3" diaginertia="0.4 0.4 0.2"/>
        <joint name="left_hinge_to_left_front_wheel" pos="0 0 0" axis="0 1 0"/>
        <geom size="0.1 0.025" quat="0.500023 0.5 0.5 -0.499977" type="cylinder" rgba="0 0 0 1"/>
      </body>
    </body>
    <body name="right_hinge" pos="0.2 0 0">
      <inertial pos="0 0 0" mass="0.01" diaginertia="5e-06 5e-06 5e-06"/>
      <joint name="base_to_right_hinge" pos="0 0 0" axis="0 0 1" range="-0.5 0.5" actuatorfrcrange="-100 100"/>
      <body name="right_front_wheel" pos="0 -0.2 0">
        <inertial pos="0 0 0" mass="0.3" diaginertia="0.4 0.4 0.2"/>
        <joint name="right_hinge_to_right_front_wheel" pos="0 0 0" axis="0 1 0"/>
        <geom size="0.1 0.025" quat="0.500023 -0.5 -0.5 -0.499977" type="cylinder" rgba="0 0 0 1"/>
      </body>
    </body>
    <body name="left_back_wheel" pos="-0.2 0.175 0">
      <inertial pos="0 0 0" mass="0.3" diaginertia="0.4 0.4 0.2"/>
      <joint name="base_to_left_back_wheel" pos="0 0 0" axis="0 1 0"/>
      <geom size="0.1 0.025" quat="0.500023 0.5 0.5 -0.499977" type="cylinder" rgba="0 0 0 1"/>
    </body>
    <body name="right_back_wheel" pos="-0.2 -0.175 0">
      <inertial pos="0 0 0" mass="0.3" diaginertia="0.4 0.4 0.2"/>
      <joint name="base_to_right_back_wheel" pos="0 0 0" axis="0 1 0"/>
      <geom size="0.1 0.025" quat="0.500023 -0.5 -0.5 -0.499977" type="cylinder" rgba="0 0 0 1"/>
    </body>
  </worldbody>
</mujoco>
