<?xml version="1.0"?>
<robot name="/home/tumin/Desktop/100daysofRobot/urdfs/diff_Drive.urdf" xmlns:xacro="http://ros.org/wiki/xacro">
  <link name="base_link">
    <visual>
      <origin xyz="0 0 0.023" rpy="0 0 0"/>
      <geometry>
        <box size="0.08 0.08 0.03"/>
      </geometry>
    </visual>
    <collision>
      <origin xyz="0 0 0.023" rpy="0 0 0"/>
      <geometry>
        <box size="0.08 0.08 0.03"/>
      </geometry>
    </collision>
  </link>
  <joint name="motor2" type="continuous">
    <parent link="base_link"/>
    <child link="solid(1)"/>
    <axis xyz="-0.001817 -0.009212 0.999956"/>
    <limit effort="10" velocity="10"/>
    <origin xyz="-0.045 0 0.025" rpy="3.138037 1.568979 -3.135935"/>
  </joint>
  <link name="solid(1)">
    <visual>
      <origin xyz="-0.00002 -0.000022 -0.000079" rpy="0 0 0"/>
      <geometry>
        <cylinder radius="0.025" length="0.01"/>
      </geometry>
    </visual>
    <collision>
      <origin xyz="-0.00002 -0.000022 -0.000079" rpy="0 0 0"/>
      <geometry>
        <cylinder radius="0.025" length="0.01"/>
      </geometry>
    </collision>
  </link>
  <joint name="motor1" type="continuous">
    <parent link="base_link"/>
    <child link="solid"/>
    <axis xyz="0.004098 0.004926 -0.999979"/>
    <limit effort="10" velocity="10"/>
    <origin xyz="0.04498 -0.000022 0.024921" rpy="-0.000066 -1.566699 -0.00486"/>
  </joint>
  <link name="solid">
    <visual>
      <origin xyz="-0.000015 -0.000031 -0.000082" rpy="0 0 0"/>
      <geometry>
        <cylinder radius="0.025" length="0.01"/>
      </geometry>
    </visual>
    <collision>
      <origin xyz="-0.000015 -0.000031 -0.000082" rpy="0 0 0"/>
      <geometry>
        <cylinder radius="0.025" length="0.01"/>
      </geometry>
    </collision>
  </link>
  <link name="compass">
  </link>
  <joint name="base_link_compass_joint" type="fixed">
    <parent link="base_link"/>
    <child link="compass"/>
    <origin xyz="-0.000015 -0.000031 0.024918" rpy="0 0 0"/>
  </joint>
</robot>
